Workbook

Sheet Life Cycle Testing
B1: Year | C1: Operating Cash Margin | D1: Operating Cash Margin(3 year Sum) | E1: (Invested)/generated from Net Working Assets | F1: (Invested)/generated from Net Working Assets (3 Year) | G1: Total Sources of cash flow for 3 years | H1: 3 Year Operating Cash Margin and Invested / Generated from Net working capital / 3 Year Total Sources of Cash Flow | I1: Revenue | J1: Five year Revenue CAGR | K1: Three year Revenue CAGR | L1: GDP | M1: Three year GDP CAGR | N1: 5 year GDP CAGR | O1: GDP Multiplier * Three year GDP CAGR | P1: Revenue Available for Less than 3 Financial Years | Q1: 3 Year Revenue CAGR Less than equal to 3 Year CAGR GDP | R1: 3 Year Revenue CAGR More than equal to 3 Year CAGR GDP But Less than equal to Multiplier time 3 Years CAGR GDP | S1: 3 Year Operating Cash Margin and Invested / Generated from Net working capital less than 30% of 3 Year Total Sources of Cash Flow | T1: 3 Year Revenue CAGR greater than equal to Multiplier Time Revenue Multiple CAGR of 3 Year Nominal GDP | U1: AND 3 Year Operating Cash Margin and Invested/ Generated from Net working capitalmore than 30% of Total Sources of Cash Flow If fails, Mark to Early Stage | V1: 3 Year Revenue CAGR is Less than equal to 5 Year Revenue CAGR | W1: 3 Year Revenue CAGR is Greater than equal to 5 Year Revenue CAGR | X1: High Growth Company | Y1: Early Stage | Z1: Low To Moderate | AA1: Attempt To Revival | AB1: Decline | AC1: Number of Years | AD1: Final Result | AE1: Frontend Displays
A2: Microsoft Corporation | B2: FY 2000 | C2: 15.426 | E2: -3.2 | I2: 22.956 | J2: -% | K2: - | L2: 10250.952 | M2: - | N2: - | O2: - | P2: 1 | AC2: =COUNT($I$2:I2) -> 1 | AD2: =IF(AC2<4,"Recently Listed",IF(X2=1,"High Growth",IF(Y2=1,"Early Stage",IF(Z2=1,"Low To Moderate",IF(AA2=1,"Attempt to Rivival",IF(AB2=1,"Decline","Undetermined")))))) -> Recently Listed
A3: Microsoft Corporation | B3: FY 2001 | C3: 15.025 | E3: -0.303 | I3: 25.296 | J3: -% | K3: - | L3: 10581.929 | M3: - | N3: - | O3: - | P3: 1 | AC3: =COUNT($I$2:I3) -> 2 | AD3: =IF(AC3<4,"Recently Listed",IF(X3=1,"High Growth",IF(Y3=1,"Early Stage",IF(Z3=1,"Low To Moderate",IF(AA3=1,"Attempt to Rivival",IF(AB3=1,"Decline","Undetermined")))))) -> Recently Listed
A4: Microsoft Corporation | B4: FY 2002 | C4: 16.64 | D4: =SUM(C2:C4) -> 47.091 | E4: -0.231 | F4: =SUM(E2:E4) -> -3.734 | G4: 49.05 | H4: =(D4+F4)/G4*100 -> 88.393476 | I4: 28.365 | J4: -% | K4: - | L4: 10929.108 | M4: - | N4: - | O4: - | P4: 1 | Q4: =IF(OR(K4="",M4="",K4="-",M4="-"),0,IF(K4<=M4,1,0)) -> 0 | R4: =IF(OR(K4="",M4="",O4="",K4="-",M4="-",O4="-"),0,IF(AND(K4>=M4,K4<=O4),1,0)) -> 0 | S4: =IF(OR(H4="",H4="-"),0,IF(H4<30,1,0)) -> 0 | T4: =IF(OR(K4="",O4="",K4="-",O4="-"),0,IF(K4>=O4,1,0)) -> 0 | U4: =IF(OR(H4="",H4="-"),0,IF(H4>30,1,0)) -> 1 | V4: =IF(OR(K4="",J4="",K4="-",J4="-"),0,IF(K4<=J4,1,0)) -> 0 | W4: =IF(OR(K4="",J4="",K4="-",J4="-"),0,IF(K4>=J4,1,0)) -> 0 | AC4: =COUNT($I$2:I4) -> 3 | AD4: =IF(AC4<4,"Recently Listed",IF(X4=1,"High Growth",IF(Y4=1,"Early Stage",IF(Z4=1,"Low To Moderate",IF(AA4=1,"Attempt to Rivival",IF(AB4=1,"Decline","Undetermined")))))) -> Recently Listed
A5: Microsoft Corporation | B5: FY 2003 | C5: 17.097 | D5: =SUM(C3:C5) -> 48.762 | E5: 1.5 | F5: =SUM(E3:E5) -> 0.966 | G5: 49.963 | H5: =(D5+F5)/G5*100 -> 99.529652 | I5: 32.187 | J5: -% | K5: =(I5/I2)^(1/3)-1 -> 0.11925256 | L5: 11456.45 | M5: =(L5/L2)^(1/3)-1 -> 0.037756084 | O5: =M5*1.3 -> 0.049082909 | P5: 0 | Q5: =IF(OR(K5="",M5="",K5="-",M5="-"),0,IF(K5<=M5,1,0)) -> 0 | R5: =IF(OR(K5="",M5="",O5="",K5="-",M5="-",O5="-"),0,IF(AND(K5>=M5,K5<=O5),1,0)) -> 0 | S5: =IF(OR(H5="",H5="-"),0,IF(H5<30,1,0)) -> 0 | T5: =IF(OR(K5="",O5="",K5="-",O5="-"),0,IF(K5>=O5,1,0)) -> 1 | U5: =IF(OR(H5="",H5="-"),0,IF(H5>30,1,0)) -> 1 | V5: =IF(OR(K5="",J5="",K5="-",J5="-"),0,IF(K5<=J5,1,0)) -> 1 | W5: =IF(OR(K5="",J5="",K5="-",J5="-"),0,IF(K5>=J5,1,0)) -> 0 | X5: =IF(AND(T5=1,U5=1),1,0) -> 1 | Y5: =IF(OR(AND(Q5=1,U5=0),AND(T5=1,U5=0)),1,0) -> 0 | Z5: =IF(R5=1,1,0) -> 0 | AA5: =IF(AND(Q5=1,W5=1),1,0) -> 0 | AB5: =IF(AND(Q5=1,V5=1),1,0) -> 0 | AC5: =COUNT($I$2:I5) -> 4 | AD5: =IF(AC5<4,"Recently Listed",IF(X5=1,"High Growth",IF(Y5=1,"Early Stage",IF(Z5=1,"Low To Moderate",IF(AA5=1,"Attempt to Rivival",IF(AB5=1,"Decline","Undetermined")))))) -> High Growth
A6: Microsoft Corporation | B6: FY 2004 | C6: 15.163 | D6: =SUM(C4:C6) -> 48.9 | E6: 1.963 | F6: =SUM(E4:E6) -> 3.232 | G6: 52.132 | H6: =(D6+F6)/G6*100 -> 100 | I6: 36.835 | J6: -% | K6: =(I6/I3)^(1/3)-1 -> 0.1334515 | L6: 12217.2 | M6: =(L6/L3)^(1/3)-1 -> 0.049064715 | O6: =M6*1.3 -> 0.06378413 | P6: 0 | Q6: =IF(OR(K6="",M6="",K6="-",M6="-"),0,IF(K6<=M6,1,0)) -> 0 | R6: =IF(OR(K6="",M6="",O6="",K6="-",M6="-",O6="-"),0,IF(AND(K6>=M6,K6<=O6),1,0)) -> 0 | S6: =IF(OR(H6="",H6="-"),0,IF(H6<30,1,0)) -> 0 | T6: =IF(OR(K6="",O6="",K6="-",O6="-"),0,IF(K6>=O6,1,0)) -> 1 | U6: =IF(OR(H6="",H6="-"),0,IF(H6>30,1,0)) -> 1 | V6: =IF(OR(K6="",J6="",K6="-",J6="-"),0,IF(K6<=J6,1,0)) -> 1 | W6: =IF(OR(K6="",J6="",K6="-",J6="-"),0,IF(K6>=J6,1,0)) -> 0 | X6: =IF(AND(T6=1,U6=1),1,0) -> 1 | Y6: =IF(OR(AND(Q6=1,U6=0),AND(T6=1,U6=0)),1,0) -> 0 | Z6: =IF(R6=1,1,0) -> 0 | AA6: =IF(AND(Q6=1,W6=1),1,0) -> 0 | AB6: =IF(AND(Q6=1,V6=1),1,0) -> 0 | AC6: =COUNT($I$2:I6) -> 5 | AD6: =IF(AC6<4,"Recently Listed",IF(X6=1,"High Growth",IF(Y6=1,"Early Stage",IF(Z6=1,"Low To Moderate",IF(AA6=1,"Attempt to Rivival",IF(AB6=1,"Decline","Undetermined")))))) -> High Growth
A7: Microsoft Corporation | B7: FY 2005 | C7: 20.731 | D7: =SUM(C5:C7) -> 52.991 | E7: 0.174 | F7: =SUM(E5:E7) -> 3.637 | G7: 64.985 | H7: =(D7+F7)/G7*100 -> 87.140109 | I7: 39.788 | J7: =(I7/I2)^(1/5)-1 -> 0.11627495 | K7: =(I7/I4)^(1/3)-1 -> 0.11941152 | L7: 13039.2 | M7: =(L7/L4)^(1/3)-1 -> 0.060609248 | N7: =(L7/L2)^(1/5)-1 -> 0.049294386 | O7: =M7*1.3 -> 0.078792023 | P7: 0 | Q7: =IF(OR(K7="",M7="",K7="-",M7="-"),0,IF(K7<=M7,1,0)) -> 0 | R7: =IF(OR(K7="",M7="",O7="",K7="-",M7="-",O7="-"),0,IF(AND(K7>=M7,K7<=O7),1,0)) -> 0 | S7: =IF(OR(H7="",H7="-"),0,IF(H7<30,1,0)) -> 0 | T7: =IF(OR(K7="",O7="",K7="-",O7="-"),0,IF(K7>=O7,1,0)) -> 1 | U7: =IF(OR(H7="",H7="-"),0,IF(H7>30,1,0)) -> 1 | V7: =IF(OR(K7="",J7="",K7="-",J7="-"),0,IF(K7<=J7,1,0)) -> 0 | W7: =IF(OR(K7="",J7="",K7="-",J7="-"),0,IF(K7>=J7,1,0)) -> 1 | X7: =IF(AND(T7=1,U7=1),1,0) -> 1 | Y7: =IF(OR(AND(Q7=1,U7=0),AND(T7=1,U7=0)),1,0) -> 0 | Z7: =IF(R7=1,1,0) -> 0 | AA7: =IF(AND(Q7=1,W7=1),1,0) -> 0 | AB7: =IF(AND(Q7=1,V7=1),1,0) -> 0 | AC7: =COUNT($I$2:I7) -> 6 | AD7: =IF(AC7<4,"Recently Listed",IF(X7=1,"High Growth",IF(Y7=1,"Early Stage",IF(Z7=1,"Low To Moderate",IF(AA7=1,"Attempt to Rivival",IF(AB7=1,"Decline","Undetermined")))))) -> High Growth
A8: Microsoft Corporation | B8: FY 2006 | C8: 21.69 | D8: =SUM(C6:C8) -> 57.584 | E8: -2.397 | F8: =SUM(E6:E8) -> -0.26 | G8: 81.409 | H8: =(D8+F8)/G8*100 -> 70.414819 | I8: 44.282 | J8: =(I8/I3)^(1/5)-1 -> 0.11849765 | K8: =(I8/I5)^(1/3)-1 -> 0.11219834 | L8: 13815.58 | M8: =(L8/L5)^(1/3)-1 -> 0.064403644 | N8: =(L8/L3)^(1/5)-1 -> 0.054777497 | O8: =M8*1.3 -> 0.083724737 | P8: 0 | Q8: =IF(OR(K8="",M8="",K8="-",M8="-"),0,IF(K8<=M8,1,0)) -> 0 | R8: =IF(OR(K8="",M8="",O8="",K8="-",M8="-",O8="-"),0,IF(AND(K8>=M8,K8<=O8),1,0)) -> 0 | S8: =IF(OR(H8="",H8="-"),0,IF(H8<30,1,0)) -> 0 | T8: =IF(OR(K8="",O8="",K8="-",O8="-"),0,IF(K8>=O8,1,0)) -> 1 | U8: =IF(OR(H8="",H8="-"),0,IF(H8>30,1,0)) -> 1 | V8: =IF(OR(K8="",J8="",K8="-",J8="-"),0,IF(K8<=J8,1,0)) -> 1 | W8: =IF(OR(K8="",J8="",K8="-",J8="-"),0,IF(K8>=J8,1,0)) -> 0 | X8: =IF(AND(T8=1,U8=1),1,0) -> 1 | Y8: =IF(OR(AND(Q8=1,U8=0),AND(T8=1,U8=0)),1,0) -> 0 | Z8: =IF(R8=1,1,0) -> 0 | AA8: =IF(AND(Q8=1,W8=1),1,0) -> 0 | AB8: =IF(AND(Q8=1,V8=1),1,0) -> 0 | AC8: =COUNT($I$2:I8) -> 7 | AD8: =IF(AC8<4,"Recently Listed",IF(X8=1,"High Growth",IF(Y8=1,"Early Stage",IF(Z8=1,"Low To Moderate",IF(AA8=1,"Attempt to Rivival",IF(AB8=1,"Decline","Undetermined")))))) -> High Growth
A9: Microsoft Corporation | B9: FY 2007 | C9: 24.034 | D9: =SUM(C7:C9) -> 66.455 | E9: -0.961 | F9: =SUM(E7:E9) -> -3.184 | G9: 110.494 | H9: =(D9+F9)/G9*100 -> 57.261933 | I9: 51.122 | J9: =(I9/I4)^(1/5)-1 -> 0.12503235 | K9: =(I9/I6)^(1/3)-1 -> 0.11544729 | L9: 14474.23 | M9: =(L9/L6)^(1/3)-1 -> 0.058135444 | N9: =(L9/L4)^(1/5)-1 -> 0.05779656 | O9: =M9*1.3 -> 0.075576077 | P9: 0 | Q9: =IF(OR(K9="",M9="",K9="-",M9="-"),0,IF(K9<=M9,1,0)) -> 0 | R9: =IF(OR(K9="",M9="",O9="",K9="-",M9="-",O9="-"),0,IF(AND(K9>=M9,K9<=O9),1,0)) -> 0 | S9: =IF(OR(H9="",H9="-"),0,IF(H9<30,1,0)) -> 0 | T9: =IF(OR(K9="",O9="",K9="-",O9="-"),0,IF(K9>=O9,1,0)) -> 1 | U9: =IF(OR(H9="",H9="-"),0,IF(H9>30,1,0)) -> 1 | V9: =IF(OR(K9="",J9="",K9="-",J9="-"),0,IF(K9<=J9,1,0)) -> 1 | W9: =IF(OR(K9="",J9="",K9="-",J9="-"),0,IF(K9>=J9,1,0)) -> 0 | X9: =IF(AND(T9=1,U9=1),1,0) -> 1 | Y9: =IF(OR(AND(Q9=1,U9=0),AND(T9=1,U9=0)),1,0) -> 0 | Z9: =IF(R9=1,1,0) -> 0 | AA9: =IF(AND(Q9=1,W9=1),1,0) -> 0 | AB9: =IF(AND(Q9=1,V9=1),1,0) -> 0 | AC9: =COUNT($I$2:I9) -> 8 | AD9: =IF(AC9<4,"Recently Listed",IF(X9=1,"High Growth",IF(Y9=1,"Early Stage",IF(Z9=1,"Low To Moderate",IF(AA9=1,"Attempt to Rivival",IF(AB9=1,"Decline","Undetermined")))))) -> High Growth
A10: Microsoft Corporation | B10: FY 2008 | C10: 29.567 | D10: =SUM(C8:C10) -> 75.291 | E10: -2.435 | F10: =SUM(E8:E10) -> -5.793 | G10: 101.883 | H10: =(D10+F10)/G10*100 -> 68.213539 | I10: 60.42 | J10: =(I10/I5)^(1/5)-1 -> 0.13422716 | K10: =(I10/I7)^(1/3)-1 -> 0.14941326 | L10: 14769.86 | M10: =(L10/L7)^(1/3)-1 -> 0.042417781 | N10: =(L10/L5)^(1/5)-1 -> 0.052119968 | O10: =M10*1.3 -> 0.055143115 | P10: 0 | Q10: =IF(OR(K10="",M10="",K10="-",M10="-"),0,IF(K10<=M10,1,0)) -> 0 | R10: =IF(OR(K10="",M10="",O10="",K10="-",M10="-",O10="-"),0,IF(AND(K10>=M10,K10<=O10),1,0)) -> 0 | S10: =IF(OR(H10="",H10="-"),0,IF(H10<30,1,0)) -> 0 | T10: =IF(OR(K10="",O10="",K10="-",O10="-"),0,IF(K10>=O10,1,0)) -> 1 | U10: =IF(OR(H10="",H10="-"),0,IF(H10>30,1,0)) -> 1 | V10: =IF(OR(K10="",J10="",K10="-",J10="-"),0,IF(K10<=J10,1,0)) -> 0 | W10: =IF(OR(K10="",J10="",K10="-",J10="-"),0,IF(K10>=J10,1,0)) -> 1 | X10: =IF(AND(T10=1,U10=1),1,0) -> 1 | Y10: =IF(OR(AND(Q10=1,U10=0),AND(T10=1,U10=0)),1,0) -> 0 | Z10: =IF(R10=1,1,0) -> 0 | AA10: =IF(AND(Q10=1,W10=1),1,0) -> 0 | AB10: =IF(AND(Q10=1,V10=1),1,0) -> 0 | AC10: =COUNT($I$2:I10) -> 9 | AD10: =IF(AC10<4,"Recently Listed",IF(X10=1,"High Growth",IF(Y10=1,"Early Stage",IF(Z10=1,"Low To Moderate",IF(AA10=1,"Attempt to Rivival",IF(AB10=1,"Decline","Undetermined")))))) -> High Growth
A11: Microsoft Corporation | B11: FY 2009 | C11: 25.867 | D11: =SUM(C9:C11) -> 79.468 | E11: -0.178 | F11: =SUM(E9:E11) -> -3.574 | G11: 90.346 | H11: =(D11+F11)/G11*100 -> 84.003719 | I11: 57.933 | J11: =(I11/I6)^(1/5)-1 -> 0.094795664 | K11: =(I11/I8)^(1/3)-1 -> 0.093703488 | L11: 14478.07 | M11: =(L11/L8)^(1/3)-1 -> 0.015735232 | N11: =(L11/L6)^(1/5)-1 -> 0.034541216 | O11: =M11*1.3 -> 0.020455801 | P11: 0 | Q11: =IF(OR(K11="",M11="",K11="-",M11="-"),0,IF(K11<=M11,1,0)) -> 0 | R11: =IF(OR(K11="",M11="",O11="",K11="-",M11="-",O11="-"),0,IF(AND(K11>=M11,K11<=O11),1,0)) -> 0 | S11: =IF(OR(H11="",H11="-"),0,IF(H11<30,1,0)) -> 0 | T11: =IF(OR(K11="",O11="",K11="-",O11="-"),0,IF(K11>=O11,1,0)) -> 1 | U11: =IF(OR(H11="",H11="-"),0,IF(H11>30,1,0)) -> 1 | V11: =IF(OR(K11="",J11="",K11="-",J11="-"),0,IF(K11<=J11,1,0)) -> 1 | W11: =IF(OR(K11="",J11="",K11="-",J11="-"),0,IF(K11>=J11,1,0)) -> 0 | X11: =IF(AND(T11=1,U11=1),1,0) -> 1 | Y11: =IF(OR(AND(Q11=1,U11=0),AND(T11=1,U11=0)),1,0) -> 0 | Z11: =IF(R11=1,1,0) -> 0 | AA11: =IF(AND(Q11=1,W11=1),1,0) -> 0 | AB11: =IF(AND(Q11=1,V11=1),1,0) -> 0 | AC11: =COUNT($I$2:I11) -> 10 | AD11: =IF(AC11<4,"Recently Listed",IF(X11=1,"High Growth",IF(Y11=1,"Early Stage",IF(Z11=1,"Low To Moderate",IF(AA11=1,"Attempt to Rivival",IF(AB11=1,"Decline","Undetermined")))))) -> High Growth
A12: Microsoft Corporation | B12: FY 2010 | C12: 27.702 | D12: =SUM(C10:C12) -> 83.136 | E12: 0.661 | F12: =SUM(E10:E12) -> -1.952 | G12: 89.678 | H12: =(D12+F12)/G12*100 -> 90.528335 | I12: 63.55 | J12: =(I12/I7)^(1/5)-1 -> 0.098177873 | K12: =(I12/I9)^(1/3)-1 -> 0.075232971 | L12: 15048.97 | M12: =(L12/L9)^(1/3)-1 -> 0.013064512 | N12: =(L12/L7)^(1/5)-1 -> 0.029084806 | O12: =M12*1.3 -> 0.016983866 | P12: 0 | Q12: =IF(OR(K12="",M12="",K12="-",M12="-"),0,IF(K12<=M12,1,0)) -> 0 | R12: =IF(OR(K12="",M12="",O12="",K12="-",M12="-",O12="-"),0,IF(AND(K12>=M12,K12<=O12),1,0)) -> 0 | S12: =IF(OR(H12="",H12="-"),0,IF(H12<30,1,0)) -> 0 | T12: =IF(OR(K12="",O12="",K12="-",O12="-"),0,IF(K12>=O12,1,0)) -> 1 | U12: =IF(OR(H12="",H12="-"),0,IF(H12>30,1,0)) -> 1 | V12: =IF(OR(K12="",J12="",K12="-",J12="-"),0,IF(K12<=J12,1,0)) -> 1 | W12: =IF(OR(K12="",J12="",K12="-",J12="-"),0,IF(K12>=J12,1,0)) -> 0 | X12: =IF(AND(T12=1,U12=1),1,0) -> 1 | Y12: =IF(OR(AND(Q12=1,U12=0),AND(T12=1,U12=0)),1,0) -> 0 | Z12: =IF(R12=1,1,0) -> 0 | AA12: =IF(AND(Q12=1,W12=1),1,0) -> 0 | AB12: =IF(AND(Q12=1,V12=1),1,0) -> 0 | AC12: =COUNT($I$2:I12) -> 11 | AD12: =IF(AC12<4,"Recently Listed",IF(X12=1,"High Growth",IF(Y12=1,"Early Stage",IF(Z12=1,"Low To Moderate",IF(AA12=1,"Attempt to Rivival",IF(AB12=1,"Decline","Undetermined")))))) -> High Growth
A13: Microsoft Corporation | B13: FY 2011 | C13: 35.511 | D13: =SUM(C11:C13) -> 89.08 | E13: -3.003 | F13: =SUM(E11:E13) -> -2.52 | G13: 101.705 | H13: =(D13+F13)/G13*100 -> 85.108893 | I13: 71.148 | J13: =(I13/I8)^(1/5)-1 -> 0.099479392 | K13: =(I13/I10)^(1/3)-1 -> 0.055992074 | L13: 15599.73 | M13: =(L13/L10)^(1/3)-1 -> 0.01838869 | N13: =(L13/L8)^(1/5)-1 -> 0.024588771 | O13: =M13*1.3 -> 0.023905297 | P13: 0 | Q13: =IF(OR(K13="",M13="",K13="-",M13="-"),0,IF(K13<=M13,1,0)) -> 0 | R13: =IF(OR(K13="",M13="",O13="",K13="-",M13="-",O13="-"),0,IF(AND(K13>=M13,K13<=O13),1,0)) -> 0 | S13: =IF(OR(H13="",H13="-"),0,IF(H13<30,1,0)) -> 0 | T13: =IF(OR(K13="",O13="",K13="-",O13="-"),0,IF(K13>=O13,1,0)) -> 1 | U13: =IF(OR(H13="",H13="-"),0,IF(H13>30,1,0)) -> 1 | V13: =IF(OR(K13="",J13="",K13="-",J13="-"),0,IF(K13<=J13,1,0)) -> 1 | W13: =IF(OR(K13="",J13="",K13="-",J13="-"),0,IF(K13>=J13,1,0)) -> 0 | X13: =IF(AND(T13=1,U13=1),1,0) -> 1 | Y13: =IF(OR(AND(Q13=1,U13=0),AND(T13=1,U13=0)),1,0) -> 0 | Z13: =IF(R13=1,1,0) -> 0 | AA13: =IF(AND(Q13=1,W13=1),1,0) -> 0 | AB13: =IF(AND(Q13=1,V13=1),1,0) -> 0 | AC13: =COUNT($I$2:I13) -> 12 | AD13: =IF(AC13<4,"Recently Listed",IF(X13=1,"High Growth",IF(Y13=1,"Early Stage",IF(Z13=1,"Low To Moderate",IF(AA13=1,"Attempt to Rivival",IF(AB13=1,"Decline","Undetermined")))))) -> High Growth
A14: Microsoft Corporation | B14: FY 2012 | C14: 35.737 | D14: =SUM(C12:C14) -> 98.95 | E14: -0.174 | F14: =SUM(E12:E14) -> -2.516 | G14: 105.1 | H14: =(D14+F14)/G14*100 -> 91.75452 | I14: 74.607 | J14: =(I14/I9)^(1/5)-1 -> 0.078535261 | K14: =(I14/I11)^(1/3)-1 -> 0.087972336 | L14: 16253.97 | M14: =(L14/L11)^(1/3)-1 -> 0.03932074 | N14: =(L14/L9)^(1/5)-1 -> 0.023464532 | O14: =M14*1.3 -> 0.051116962 | P14: 0 | Q14: =IF(OR(K14="",M14="",K14="-",M14="-"),0,IF(K14<=M14,1,0)) -> 0 | R14: =IF(OR(K14="",M14="",O14="",K14="-",M14="-",O14="-"),0,IF(AND(K14>=M14,K14<=O14),1,0)) -> 0 | S14: =IF(OR(H14="",H14="-"),0,IF(H14<30,1,0)) -> 0 | T14: =IF(OR(K14="",O14="",K14="-",O14="-"),0,IF(K14>=O14,1,0)) -> 1 | U14: =IF(OR(H14="",H14="-"),0,IF(H14>30,1,0)) -> 1 | V14: =IF(OR(K14="",J14="",K14="-",J14="-"),0,IF(K14<=J14,1,0)) -> 0 | W14: =IF(OR(K14="",J14="",K14="-",J14="-"),0,IF(K14>=J14,1,0)) -> 1 | X14: =IF(AND(T14=1,U14=1),1,0) -> 1 | Y14: =IF(OR(AND(Q14=1,U14=0),AND(T14=1,U14=0)),1,0) -> 0 | Z14: =IF(R14=1,1,0) -> 0 | AA14: =IF(AND(Q14=1,W14=1),1,0) -> 0 | AB14: =IF(AND(Q14=1,V14=1),1,0) -> 0 | AC14: =COUNT($I$2:I14) -> 13 | AD14: =IF(AC14<4,"Recently Listed",IF(X14=1,"High Growth",IF(Y14=1,"Early Stage",IF(Z14=1,"Low To Moderate",IF(AA14=1,"Attempt to Rivival",IF(AB14=1,"Decline","Undetermined")))))) -> High Growth
A15: Microsoft Corporation | B15: FY 2013 | C15: 34.688 | D15: =SUM(C13:C15) -> 105.936 | E15: -1.375 | F15: =SUM(E13:E15) -> -4.552 | G15: 117.134 | H15: =(D15+F15)/G15*100 -> 86.553861 | I15: 78.566 | J15: =(I15/I10)^(1/5)-1 -> 0.053927616 | K15: =(I15/I12)^(1/3)-1 -> 0.073263507 | L15: 16880.68 | M15: =(L15/L12)^(1/3)-1 -> 0.039029122 | N15: =(L15/L10)^(1/5)-1 -> 0.027076309 | O15: =M15*1.3 -> 0.050737859 | P15: 0 | Q15: =IF(OR(K15="",M15="",K15="-",M15="-"),0,IF(K15<=M15,1,0)) -> 0 | R15: =IF(OR(K15="",M15="",O15="",K15="-",M15="-",O15="-"),0,IF(AND(K15>=M15,K15<=O15),1,0)) -> 0 | S15: =IF(OR(H15="",H15="-"),0,IF(H15<30,1,0)) -> 0 | T15: =IF(OR(K15="",O15="",K15="-",O15="-"),0,IF(K15>=O15,1,0)) -> 1 | U15: =IF(OR(H15="",H15="-"),0,IF(H15>30,1,0)) -> 1 | V15: =IF(OR(K15="",J15="",K15="-",J15="-"),0,IF(K15<=J15,1,0)) -> 0 | W15: =IF(OR(K15="",J15="",K15="-",J15="-"),0,IF(K15>=J15,1,0)) -> 1 | X15: =IF(AND(T15=1,U15=1),1,0) -> 1 | Y15: =IF(OR(AND(Q15=1,U15=0),AND(T15=1,U15=0)),1,0) -> 0 | Z15: =IF(R15=1,1,0) -> 0 | AA15: =IF(AND(Q15=1,W15=1),1,0) -> 0 | AB15: =IF(AND(Q15=1,V15=1),1,0) -> 0 | AC15: =COUNT($I$2:I15) -> 14 | AD15: =IF(AC15<4,"Recently Listed",IF(X15=1,"High Growth",IF(Y15=1,"Early Stage",IF(Z15=1,"Low To Moderate",IF(AA15=1,"Attempt to Rivival",IF(AB15=1,"Decline","Undetermined")))))) -> High Growth
A16: Microsoft Corporation | B16: FY 2014 | C16: 37.887 | D16: =SUM(C14:C16) -> 108.312 | E16: 0.624 | F16: =SUM(E14:E16) -> -0.925 | G16: 119.752 | H16: =(D16+F16)/G16*100 -> 89.674494 | I16: 87.491 | J16: =(I16/I11)^(1/5)-1 -> 0.085944106 | K16: =(I16/I13)^(1/3)-1 -> 0.071355396 | L16: 17608.14 | M16: =(L16/L13)^(1/3)-1 -> 0.041195143 | N16: =(L16/L11)^(1/5)-1 -> 0.039921512 | O16: =M16*1.3 -> 0.053553686 | P16: 0 | Q16: =IF(OR(K16="",M16="",K16="-",M16="-"),0,IF(K16<=M16,1,0)) -> 0 | R16: =IF(OR(K16="",M16="",O16="",K16="-",M16="-",O16="-"),0,IF(AND(K16>=M16,K16<=O16),1,0)) -> 0 | S16: =IF(OR(H16="",H16="-"),0,IF(H16<30,1,0)) -> 0 | T16: =IF(OR(K16="",O16="",K16="-",O16="-"),0,IF(K16>=O16,1,0)) -> 1 | U16: =IF(OR(H16="",H16="-"),0,IF(H16>30,1,0)) -> 1 | V16: =IF(OR(K16="",J16="",K16="-",J16="-"),0,IF(K16<=J16,1,0)) -> 1 | W16: =IF(OR(K16="",J16="",K16="-",J16="-"),0,IF(K16>=J16,1,0)) -> 0 | X16: =IF(AND(T16=1,U16=1),1,0) -> 1 | Y16: =IF(OR(AND(Q16=1,U16=0),AND(T16=1,U16=0)),1,0) -> 0 | Z16: =IF(R16=1,1,0) -> 0 | AA16: =IF(AND(Q16=1,W16=1),1,0) -> 0 | AB16: =IF(AND(Q16=1,V16=1),1,0) -> 0 | AC16: =COUNT($I$2:I16) -> 15 | AD16: =IF(AC16<4,"Recently Listed",IF(X16=1,"High Growth",IF(Y16=1,"Early Stage",IF(Z16=1,"Low To Moderate",IF(AA16=1,"Attempt to Rivival",IF(AB16=1,"Decline","Undetermined")))))) -> High Growth
A17: Microsoft Corporation | B17: FY 2015 | C17: 33.175 | D17: =SUM(C15:C17) -> 105.75 | E17: 1.513 | F17: =SUM(E15:E17) -> 0.762 | G17: 132.328 | H17: =(D17+F17)/G17*100 -> 80.490901 | I17: 96.148 | J17: =(I17/I12)^(1/5)-1 -> 0.086337921 | K17: =(I17/I14)^(1/3)-1 -> 0.088228827 | L17: 18295.02 | M17: =(L17/L14)^(1/3)-1 -> 0.040218272 | N17: =(L17/L12)^(1/5)-1 -> 0.039836894 | O17: =M17*1.3 -> 0.052283754 | P17: 0 | Q17: =IF(OR(K17="",M17="",K17="-",M17="-"),0,IF(K17<=M17,1,0)) -> 0 | R17: =IF(OR(K17="",M17="",O17="",K17="-",M17="-",O17="-"),0,IF(AND(K17>=M17,K17<=O17),1,0)) -> 0 | S17: =IF(OR(H17="",H17="-"),0,IF(H17<30,1,0)) -> 0 | T17: =IF(OR(K17="",O17="",K17="-",O17="-"),0,IF(K17>=O17,1,0)) -> 1 | U17: =IF(OR(H17="",H17="-"),0,IF(H17>30,1,0)) -> 1 | V17: =IF(OR(K17="",J17="",K17="-",J17="-"),0,IF(K17<=J17,1,0)) -> 0 | W17: =IF(OR(K17="",J17="",K17="-",J17="-"),0,IF(K17>=J17,1,0)) -> 1 | X17: =IF(AND(T17=1,U17=1),1,0) -> 1 | Y17: =IF(OR(AND(Q17=1,U17=0),AND(T17=1,U17=0)),1,0) -> 0 | Z17: =IF(R17=1,1,0) -> 0 | AA17: =IF(AND(Q17=1,W17=1),1,0) -> 0 | AB17: =IF(AND(Q17=1,V17=1),1,0) -> 0 | AC17: =COUNT($I$2:I17) -> 16 | AD17: =IF(AC17<4,"Recently Listed",IF(X17=1,"High Growth",IF(Y17=1,"Early Stage",IF(Z17=1,"Low To Moderate",IF(AA17=1,"Attempt to Rivival",IF(AB17=1,"Decline","Undetermined")))))) -> High Growth
A18: Microsoft Corporation | B18: FY 2016 | C18: 40.401 | D18: =SUM(C16:C18) -> 111.463 | E18: -2.076 | F18: =SUM(E16:E18) -> 0.061 | G18: 111.524 | H18: =(D18+F18)/G18*100 -> 100 | I18: 86.132 | J18: =(I18/I13)^(1/5)-1 -> 0.038963683 | K18: =(I18/I15)^(1/3)-1 -> 0.031121786 | L18: 18804.91 | M18: =(L18/L15)^(1/3)-1 -> 0.036637959 | N18: =(L18/L13)^(1/5)-1 -> 0.038080028 | O18: =M18*1.3 -> 0.047629346 | P18: 0 | Q18: =IF(OR(K18="",M18="",K18="-",M18="-"),0,IF(K18<=M18,1,0)) -> 1 | R18: =IF(OR(K18="",M18="",O18="",K18="-",M18="-",O18="-"),0,IF(AND(K18>=M18,K18<=O18),1,0)) -> 0 | S18: =IF(OR(H18="",H18="-"),0,IF(H18<30,1,0)) -> 0 | T18: =IF(OR(K18="",O18="",K18="-",O18="-"),0,IF(K18>=O18,1,0)) -> 0 | U18: =IF(OR(H18="",H18="-"),0,IF(H18>30,1,0)) -> 1 | V18: =IF(OR(K18="",J18="",K18="-",J18="-"),0,IF(K18<=J18,1,0)) -> 1 | W18: =IF(OR(K18="",J18="",K18="-",J18="-"),0,IF(K18>=J18,1,0)) -> 0 | X18: =IF(AND(T18=1,U18=1),1,0) -> 0 | Y18: =IF(OR(AND(Q18=1,U18=0),AND(T18=1,U18=0)),1,0) -> 0 | Z18: =IF(R18=1,1,0) -> 0 | AA18: =IF(AND(Q18=1,W18=1),1,0) -> 0 | AB18: =IF(AND(Q18=1,V18=1),1,0) -> 1 | AC18: =COUNT($I$2:I18) -> 17 | AD18: =IF(AC18<4,"Recently Listed",IF(X18=1,"High Growth",IF(Y18=1,"Early Stage",IF(Z18=1,"Low To Moderate",IF(AA18=1,"Attempt to Rivival",IF(AB18=1,"Decline","Undetermined")))))) -> Decline
... A26: Microsoft Corporation | B26: FY 2024 | C26: 123.97 | D26: =SUM(C24:C26) -> 328.882 | E26: 19.678 | F26: =SUM(E24:E26) -> 34.083 | G26: 401.769 | H26: =(D26+F26)/G26*100 -> 90.341714 | I26: 245.122 | J26: =(I26/I21)^(1/5)-1 -> 0.13654592 | K26: =(I26/I23)^(1/3)-1 -> 0.12617219 | L26: 29167.78 | M26: =(L26/L23)^(1/3)-1 -> 0.071930776 | N26: =(L26/L21)^(1/5)-1 -> 0.06250655 | O26: =M26*1.3 -> 0.093510009 | P26: 0 | Q26: =IF(OR(K26="",M26="",K26="-",M26="-"),0,IF(K26<=M26,1,0)) -> 0 | R26: =IF(OR(K26="",M26="",O26="",K26="-",M26="-",O26="-"),0,IF(AND(K26>=M26,K26<=O26),1,0)) -> 0 | S26: =IF(OR(H26="",H26="-"),0,IF(H26<30,1,0)) -> 0 | T26: =IF(OR(K26="",O26="",K26="-",O26="-"),0,IF(K26>=O26,1,0)) -> 1 | U26: =IF(OR(H26="",H26="-"),0,IF(H26>30,1,0)) -> 1 | V26: =IF(OR(K26="",J26="",K26="-",J26="-"),0,IF(K26<=J26,1,0)) -> 1 | W26: =IF(OR(K26="",J26="",K26="-",J26="-"),0,IF(K26>=J26,1,0)) -> 0 | X26: =IF(AND(T26=1,U26=1),1,0) -> 1 | Y26: =IF(OR(AND(Q26=1,U26=0),AND(T26=1,U26=0)),1,0) -> 0 | Z26: =IF(R26=1,1,0) -> 0 | AA26: =IF(AND(Q26=1,W26=1),1,0) -> 0 | AB26: =IF(AND(Q26=1,V26=1),1,0) -> 0 | AC26: =COUNT($I$2:I26) -> 25 | AD26: =IF(AC26<4,"Recently Listed",IF(X26=1,"High Growth",IF(Y26=1,"Early Stage",IF(Z26=1,"Low To Moderate",IF(AA26=1,"Attempt to Rivival",IF(AB26=1,"Decline","Undetermined")))))) -> High Growth
A27: Microsoft Corporation | B27: FY 2025 | C27: 171.812 | D27: =SUM(C25:C27) -> 402.554 | E27: -5.35 | F27: =SUM(E25:E27) -> 19.938 | G27: 443.817 | H27: =(D27+F27)/G27*100 -> 95.195092 | I27: 276.823 | J27: =(I27/I22)^(1/5)-1 -> 0.13699527 | K27: =(I27/I24)^(1/3)-1 -> 0.11704874 | P27: 0 | Q27: =IF(OR(K27="",M27="",K27="-",M27="-"),0,IF(K27<=M27,1,0)) -> 0 | R27: =IF(OR(K27="",M27="",O27="",K27="-",M27="-",O27="-"),0,IF(AND(K27>=M27,K27<=O27),1,0)) -> 0 | S27: =IF(OR(H27="",H27="-"),0,IF(H27<30,1,0)) -> 0 | T27: =IF(OR(K27="",O27="",K27="-",O27="-"),0,IF(K27>=O27,1,0)) -> 0 | U27: =IF(OR(H27="",H27="-"),0,IF(H27>30,1,0)) -> 1 | V27: =IF(OR(K27="",J27="",K27="-",J27="-"),0,IF(K27<=J27,1,0)) -> 1 | W27: =IF(OR(K27="",J27="",K27="-",J27="-"),0,IF(K27>=J27,1,0)) -> 0 | X27: =IF(AND(T27=1,U27=1),1,0) -> 0 | Y27: =IF(OR(AND(Q27=1,U27=0),AND(T27=1,U27=0)),1,0) -> 0 | Z27: =IF(R27=1,1,0) -> 0 | AA27: =IF(AND(Q27=1,W27=1),1,0) -> 0 | AB27: =IF(AND(Q27=1,V27=1),1,0) -> 0 | AC27: =COUNT($I$2:I27) -> 26 | AD27: =IF(AC27<4,"Recently Listed",IF(X27=1,"High Growth",IF(Y27=1,"Early Stage",IF(Z27=1,"Low To Moderate",IF(AA27=1,"Attempt to Rivival",IF(AB27=1,"Decline","Undetermined")))))) -> Undetermined | AE27: High Growth

Sheet Sheet17
A1: Amount in BUSD | B1: 36678 | C1: 37043 | D1: 37408 | E1: 37773 | F1: 38139 | G1: 38504 | H1: 38869 | I1: 39234 | J1: 39600 | K1: 39965 | L1: 40330 | M1: 40695 | N1: 41061 | O1: 41426 | P1: 41791 | Q1: 42156 | R1: 42522 | S1: 42887 | T1: 43252 | U1: 43617 | V1: 43983 | W1: 44348 | X1: 44713 | Y1: 45078 | Z1: 45444 | AA1: 45809
A2: Operating Cash Margin | B2: 15.426 | C2: 15.025 | D2: 16.64 | E2: 17.097 | F2: 15.163 | G2: 20.731 | H2: 21.69 | I2: 24.034 | J2: 29.567 | K2: 25.867 | L2: 27.702 | M2: 35.511 | N2: 35.737 | O2: 34.688 | P2: 37.887 | Q2: 33.175 | R2: 40.401 | S2: 41.855 | T2: 31.317 | U2: 59.119 | V2: 77.058 | W2: 93.076 | X2: 98.14 | Y2: 106.772 | Z2: 123.97 | AA2: 171.812 | AB2: =SUM(B2:D2) -> 47.091 | AC2: =SUM(C2:E2) -> 48.762 | AD2: =SUM(D2:F2) -> 48.9 | AE2: =SUM(E2:G2) -> 52.991 | AF2: =SUM(F2:H2) -> 57.584 | AG2: =SUM(G2:I2) -> 66.455 | AH2: =SUM(H2:J2) -> 75.291 | AI2: =SUM(I2:K2) -> 79.468 | ... AY2: =SUM(Y2:AA2) -> 402.554
A3: Exceptional Items | B3: 0 | C3: 0 | D3: 0 | E3: 0 | F3: 0 | G3: 0 | H3: 0 | I3: 0 | J3: 0 | K3: 0 | L3: 0 | M3: 0 | N3: 0 | O3: 0 | P3: 0 | Q3: 0 | R3: 0 | S3: 0 | T3: 0 | U3: 0 | V3: 0 | W3: 0 | X3: 0 | Y3: 0 | Z3: 0 | AA3: 0 | AB3: =SUM(B3:D3) -> 0 | AC3: =SUM(C3:E3) -> 0 | AD3: =SUM(D3:F3) -> 0 | AE3: =SUM(E3:G3) -> 0 | AF3: =SUM(F3:H3) -> 0 | AG3: =SUM(G3:I3) -> 0 | AH3: =SUM(H3:J3) -> 0 | AI3: =SUM(I3:K3) -> 0 | ... AY3: =SUM(Y3:AA3) -> 0
A4: (Invested)/generated From Net Working Assets | B4: -3.2 | C4: -0.303 | D4: -0.231 | E4: 1.5 | F4: 1.963 | G4: 0.174 | H4: -2.397 | I4: -0.961 | J4: -2.435 | K4: -0.178 | L4: 0.661 | M4: -3.003 | N4: -0.174 | O4: -1.375 | P4: 0.624 | Q4: 1.513 | R4: -2.076 | S4: 1.652 | T4: 20.467 | U4: 3.866 | V4: -1.483 | W4: -0.936 | X4: 8.795 | Y4: 5.61 | Z4: 19.678 | AA4: -5.35 | AB4: =SUM(B4:D4) -> -3.734 | AC4: =SUM(C4:E4) -> 0.966 | AD4: =SUM(D4:F4) -> 3.232 | AE4: =SUM(E4:G4) -> 3.637 | AF4: =SUM(F4:H4) -> -0.26 | AG4: =SUM(G4:I4) -> -3.184 | AH4: =SUM(H4:J4) -> -5.793 | AI4: =SUM(I4:K4) -> -3.574 | ... AY4: =SUM(Y4:AA4) -> 19.938
A5: NET Capex | B5: -0.879 | C5: -1.103 | D5: -0.77 | E5: -1.954 | F5: -1.113 | G5: -1.019 | H5: -2.227 | I5: -3.414 | J5: -11.235 | K5: -3.987 | L5: -2.222 | M5: -2.426 | N5: -12.417 | O5: -5.841 | P5: -11.422 | Q5: -9.667 | R5: -9.736 | S5: -34.073 | T5: -12.52 | U5: -16.313 | V5: -17.962 | W5: -29.531 | X5: -45.924 | Y5: -29.777 | Z5: -113.609 | AA5: -70.529 | AB5: =SUM(B5:D5) -> -2.752 | AC5: =SUM(C5:E5) -> -3.827 | AD5: =SUM(D5:F5) -> -3.837 | AE5: =SUM(E5:G5) -> -4.086 | AF5: =SUM(F5:H5) -> -4.359 | AG5: =SUM(G5:I5) -> -6.66 | AH5: =SUM(H5:J5) -> -16.876 | AI5: =SUM(I5:K5) -> -18.636 | ... AY5: =SUM(Y5:AA5) -> -213.915
A6: Taxation | B6: -0.8 | C6: -1.3 | D6: -1.9 | E6: -2.8 | F6: -2.5 | G6: -4.3 | H6: -4.8 | I6: -5.2 | J6: -5.4 | K6: -6.6 | L6: -4.1 | M6: -5.3 | N6: -3.5 | O6: -3.9 | P6: -5.5 | Q6: -4.4 | R6: -3.9 | S6: -2.4 | T6: -5.5 | U6: -8.4 | V6: -12.5 | W6: -13.4 | X6: -16 | Y6: -23.1 | Z6: -23.4 | AA6: -28.7 | AB6: =SUM(B6:D6) -> -4 | AC6: =SUM(C6:E6) -> -6 | AD6: =SUM(D6:F6) -> -7.2 | AE6: =SUM(E6:G6) -> -9.6 | AF6: =SUM(F6:H6) -> -11.6 | AG6: =SUM(G6:I6) -> -14.3 | AH6: =SUM(H6:J6) -> -15.4 | AI6: =SUM(I6:K6) -> -17.2 | ... AY6: =SUM(Y6:AA6) -> -75.2
A7: Cash Available To Satisfy Finance Providers | B7: 10.547 | C7: 12.319 | D7: 13.739 | E7: 13.843 | F7: 13.513 | G7: 15.586 | H7: 12.266 | I7: 14.459 | J7: 10.497 | K7: 15.102 | L7: 22.041 | M7: 24.782 | N7: 19.646 | O7: 23.572 | P7: 21.589 | Q7: 20.621 | R7: 24.689 | S7: 7.034 | T7: 33.764 | U7: 38.272 | V7: 45.113 | W7: 49.209 | X7: 45.011 | Y7: 59.505 | Z7: 6.639 | AA7: 67.233 | AB7: =SUM(B7:D7) -> 36.605 | AC7: =SUM(C7:E7) -> 39.901 | AD7: =SUM(D7:F7) -> 41.095 | AE7: =SUM(E7:G7) -> 42.942 | AF7: =SUM(F7:H7) -> 41.365 | AG7: =SUM(G7:I7) -> 42.311 | AH7: =SUM(H7:J7) -> 37.222 | AI7: =SUM(I7:K7) -> 40.058 | ... AY7: =SUM(Y7:AA7) -> 133.377
A8: Debt Service Cost Paid | B8: 0 | C8: 0 | D8: 0 | E8: 0 | F8: 0 | G8: 0 | H8: 0 | I8: 0 | J8: 0 | K8: 0 | L8: -0.145 | M8: -0.197 | N8: -0.344 | O8: -0.371 | P8: -0.509 | Q8: -0.62 | R8: -1.1 | S8: -1.6 | T8: -2.4 | U8: -2.4 | V8: -2.4 | W8: -2 | X8: -1.9 | Y8: -1.7 | Z8: -1.7 | AA8: -1.6 | AB8: =SUM(B8:D8) -> 0 | AC8: =SUM(C8:E8) -> 0 | AD8: =SUM(D8:F8) -> 0 | AE8: =SUM(E8:G8) -> 0 | AF8: =SUM(F8:H8) -> 0 | AG8: =SUM(G8:I8) -> 0 | AH8: =SUM(H8:J8) -> 0 | AI8: =SUM(I8:K8) -> 0 | ... AY8: =SUM(Y8:AA8) -> -5
A9: Dividend & Dividend Tax Paid | B9: -0.013 | C9: 0 | D9: 0 | E9: -0.857 | F9: -1.729 | G9: -36.112 | H9: -3.545 | I9: -3.805 | J9: -4.015 | K9: -4.468 | L9: -4.578 | M9: -5.18 | N9: -6.385 | O9: -7.455 | P9: -8.879 | Q9: -9.882 | R9: -11.006 | S9: -11.845 | T9: -12.699 | U9: -13.811 | V9: -15.137 | W9: -16.521 | X9: -18.135 | Y9: -19.8 | Z9: -21.771 | AA9: -24.082 | AB9: =SUM(B9:D9) -> -0.013 | AC9: =SUM(C9:E9) -> -0.857 | AD9: =SUM(D9:F9) -> -2.586 | AE9: =SUM(E9:G9) -> -38.698 | AF9: =SUM(F9:H9) -> -41.386 | AG9: =SUM(G9:I9) -> -43.462 | AH9: =SUM(H9:J9) -> -11.365 | AI9: =SUM(I9:K9) -> -12.288 | ... AY9: =SUM(Y9:AA9) -> -65.653
A10: Investments/Loans & Advances | B10: -8.484 | C10: -7.657 | D10: -10.073 | E10: -5.48 | F10: -2.202 | G10: 16.039 | H10: 10.248 | I10: 9.559 | J10: 6.785 | K10: -11.85 | L10: -9.131 | M10: -12.087 | N10: -12.473 | O10: -17.978 | P10: -7.55 | Q10: -13.407 | R10: -14.281 | S10: -12.689 | T10: 6.509 | U10: 0.425 | V10: 5.538 | W10: 1.925 | X10: 15.472 | Y10: 6.903 | Z10: 16.429 | AA10: -2.007 | AB10: =SUM(B10:D10) -> -26.214 | AC10: =SUM(C10:E10) -> -23.21 | AD10: =SUM(D10:F10) -> -17.755 | AE10: =SUM(E10:G10) -> 8.357 | AF10: =SUM(F10:H10) -> 24.085 | AG10: =SUM(G10:I10) -> 35.846 | AH10: =SUM(H10:J10) -> 26.592 | AI10: =SUM(I10:K10) -> 4.494 | ... AY10: =SUM(Y10:AA10) -> 21.325
A11: Net Cash generated/(Absorbed) Before Financing | B11: 2.05 | C11: 4.662 | D11: 3.666 | E11: 7.506 | F11: 9.582 | G11: -4.487 | H11: 18.969 | I11: 20.213 | J11: 13.267 | K11: -1.216 | L11: 8.187 | M11: 7.318 | N11: 0.444 | O11: -2.232 | P11: 4.651 | Q11: -3.288 | R11: -1.698 | S11: -19.1 | T11: 25.174 | U11: 22.486 | V11: 33.114 | W11: 32.613 | X11: 40.448 | Y11: 44.908 | Z11: -0.403 | AA11: 39.544 | AB11: =SUM(B11:D11) -> 10.378 | AC11: =SUM(C11:E11) -> 15.834 | AD11: =SUM(D11:F11) -> 20.754 | AE11: =SUM(E11:G11) -> 12.601 | AF11: =SUM(F11:H11) -> 24.064 | AG11: =SUM(G11:I11) -> 34.695 | AH11: =SUM(H11:J11) -> 52.449 | AI11: =SUM(I11:K11) -> 32.264 | ... AY11: =SUM(Y11:AA11) -> 84.049
A12: Increase/(decrease) In Equity | B12: -2.179 | C12: -5.821 | D12: -4.572 | E12: -4.366 | F12: -0.635 | G12: -4.948 | H12: -17.106 | I12: -20.793 | J12: -9.039 | K12: -8.774 | L12: -8.958 | M12: -9.133 | N12: -3.116 | O12: -4.429 | P12: -6.709 | Q12: -13.809 | R12: -15.301 | S12: -11.016 | T12: -9.719 | U12: -18.401 | V12: -21.625 | W12: -25.692 | X12: -30.855 | Y12: -20.379 | Z12: -15.252 | AA12: -16.364 | AB12: =SUM(B12:D12) -> -12.572 | AC12: =SUM(C12:E12) -> -14.759 | AD12: =SUM(D12:F12) -> -9.573 | AE12: =SUM(E12:G12) -> -9.949 | AF12: =SUM(F12:H12) -> -22.689 | AG12: =SUM(G12:I12) -> -42.847 | AH12: =SUM(H12:J12) -> -46.938 | AI12: =SUM(I12:K12) -> -38.606 | ... AY12: =SUM(Y12:AA12) -> -51.995
A13: Increase/(decrease) In Debt | B13: 0 | C13: 0 | D13: 0 | E13: 0 | F13: 0 | G13: 0 | H13: 0 | I13: 0 | J13: 0 | K13: 5.746 | L13: 0.19 | M13: 5.96 | N13: 0 | O13: 3.537 | P13: 6.962 | Q13: 13.661 | R13: 18.283 | S13: 31.459 | T13: -10.201 | U13: -4 | V13: -8.935 | W13: -5.504 | X13: -9.023 | Y13: -2.75 | Z13: 0.575 | AA13: -8.962 | AB13: =SUM(B13:D13) -> 0 | AC13: =SUM(C13:E13) -> 0 | AD13: =SUM(D13:F13) -> 0 | AE13: =SUM(E13:G13) -> 0 | AF13: =SUM(F13:H13) -> 0 | AG13: =SUM(G13:I13) -> 0 | AH13: =SUM(H13:J13) -> 0 | AI13: =SUM(I13:K13) -> 5.746 | ... AY13: =SUM(Y13:AA13) -> -11.137
... A17: (Increase)/Decrease In Cash | B17: 0.129 | C17: 0.924 | D17: 0.906 | E17: -3.14 | F17: -8.947 | G17: 9.453 | H17: -1.863 | I17: 0.603 | J17: -4.228 | K17: 4.263 | L17: 0.571 | M17: -4.105 | N17: 2.672 | O17: 3.134 | P17: -4.865 | Q17: 3.074 | R17: -0.915 | S17: -1.153 | T17: -4.283 | U17: 0.59 | V17: -2.22 | W17: -0.648 | X17: 0.293 | Y17: -20.773 | Z17: 16.389 | AA17: -11.927 | AB17: =SUM(B17:D17) -> 1.959 | AC17: =SUM(C17:E17) -> -1.31 | AD17: =SUM(D17:F17) -> -11.181 | AE17: =SUM(E17:G17) -> -2.634 | AF17: =SUM(F17:H17) -> -1.357 | AG17: =SUM(G17:I17) -> 8.193 | AH17: =SUM(H17:J17) -> -5.488 | AI17: =SUM(I17:K17) -> 0.638 | ... AY17: =SUM(Y17:AA17) -> -16.311
AB18: =AB15+AB17+AB2 -> 49.05 | AC18: =AC15+AC14+AC4+AC2 -> 49.963 | AD18: =AD15+AD4+AD2 -> 52.132 | AE18: =AE15+AE10+AE4+AE2 -> 64.985 | AF18: =AF15+AF10+AF4+AF2 -> 81.409 | AG18: =AG15+AG17+AG2+AG13+AG10 -> 110.494 | AH18: =AH15+AH10+AH2 -> 101.883 | AI18: =AI15+AI17+AI2+AI13+AI10 -> 90.346 | AJ18: =AJ15+AJ17+AJ2+AJ13 -> 89.678 | AK18: =AK15+AK17+AK2+AK13 -> 101.705 | AL18: =AL15+AL13+AL2 -> 105.1 | AM18: =AM15+AM17+AM2+AM13 -> 117.134 | AN18: =AN15+AN17+AN2+AN13 -> 119.752 | AO18: =AO15+AO17+AO4+AO2+AO13+AO14 -> 132.328 | AP18: =AP15+AP4+AP2 -> 111.524 | AQ18: =AQ15+AQ17+AQ4+AQ2 -> 117.526 | AR18: =AR15+AR10+AR4+AR2 -> 113.155 | AS18: =AS15+AS10+AS4+AS2 -> 152.521 | AT18: =AT15+AT10+AT4+AT2 -> 202.816 | AU18: =AU15+AU10+AU4+AU2 -> 238.588 | AV18: =AV15+AV10+AV4+AV2 -> 297.585 | AW18: =AW15+AW10+AW4+AW2 -> 335.757 | AX18: =AX15+AX10+AX4+AX2 -> 401.769 | AY18: =AY15+AY10+AY4+AY2 -> 443.817

Sheet Micro Valuation Calculation
A1: STOCK PERFORMANCE CHART | P1: Total outstanding share including future commitment | S1: Market Capitalization Evolution | AA1: Market Valuation Components and Implied Earning Growth Rates | AI1: Earning Yield Comparison | AL1: Price Earning Ratio | AQ1: Comparative Price to Earning | AV1: Price to Book Value/Price to Sales | BB1: Cash Flow Yields | BG1: Net Asset Value Comparisons | BS1: Market Cap Co-relation with Underlying Business | CF1: Free Cash Flow Based Valuation
A2: Company Name | B2: Years | C2: Operating Cash Margin | D2: Market Cap | E2: Revenue | F2: S&P 500 | G2: Net Profit (W/o Excep Items) | H2: Price To Earning Ratio | I2: Price To Earning Ratio(Excep) | J2: NET Capex | K2: Taxation | L2: (Invested)/generated from Net Working Assets | M2: Debt Service Cost Paid | N2: Free Cash Flow | P2: Total Outstanding Share | Q2: Total Outstanding Share (%Growth) | S2: Share Price Per Share | T2: Market Capitalization | U2: Mcap Growth % | V2: Equity | W2: Equity (%Growth) | X2: Net Tangible Asset Value | Y2: Net Tangible Asset Value (%Growth) | AA2: Hurdle rate | AB2: Equity | AC2: Book Value (Previous Year) Component of Market Valuation | AD2: No Growth Scenario Component of Market Valuation | AE2: Speculative Value Component of Market Valuation | AF2: Implied Growth Rate to Reach Market Valuation | AG2: Check for Ratio | AI2: Net Profit After Tax | AJ2: Net Profit (W/o Excep Items) | AL2: Net Profit After Tax | AM2: Price to Earning Ratio | AN2: Net Profit (W/o Excep Items) | AO2: Price to Earning Ratio (Excep Items) | AQ2: Comparative Price to Earning | AR2: Price To Earnings (Average (All Year To Latest) | AS2: Comparative Price to Earning (Excep Items) | AT2: Price To Earnings (Average (All Year To Latest) | AV2: Mcap to Equity | AW2: Mcap to Revenue | AX2: Intangible Assets | AY2: Net Tangible Asset | AZ2: Mcap to Net Tangible Asset | BB2: Cash Available to Satisfy Finance Providers | BC2: Net Cash generated/(Absorbed) before Financing | BD2: Cash Flow Available to Satisfy Finance Providers Yield | BE2: Cash Flow Availability before Financing Yield | BG2: Share Price Per Share | BH2: Total Outstanding Share | BI2: Market Capitalization | BJ2: Equity | BK2: Net Tangible Asset Value | BL2: Current assets | BM2: Current Liabilities | BN2: Non-current Liabilities | BO2: Net Current Asset Value | BP2: Cash and cash equivalents | BQ2: Net Cash Asset Value | BS2: Mcap | BT2: Revenue | BU2: Free Cash Flow (Excep Items) | BV2: Npat (Excep Items) | BW2: 5 Years Mcap | BX2: 5 Years Revenue | BY2: 5 Years FCF | BZ2: 5 Years Npat(Excep Items | CA2: 10 Years Mcap | CB2: 10 Years Revenue | CC2: 10 Years FCF | CD2: 10 Years Npat(Excep Items | CF2: Market Cap | CG2: Free Cash Flows | CH2: Free Cash Flows to Dereive Market Cap(RHS) | CI2: Teasury Yield | CJ2: Numers | CK2: Latest Firm value1% | CL2: Latest Firm value2% | CM2: Firm value3% | CN2: Firm value3.87% | CO2: Firm value4% | CP2: Firm value 5% | CQ2: Firm value6% | CR2: Firm value6.62% | CS2: Firm value8% | CT2: Firm value9% | CU2: Firm value10% | CV2: Firm value11% | CW2: Firm value12% | CX2: Firm value13% | CY2: Firm value14% | CZ2: Firm value15% | DA2: Free Cash Flow (Latest Average Based Valuation)1%...15% | DB2: 3..All Years Average | DC2: 3year Average Firm value1% | DD2: 3year Average Firm value2% | DE2: 3year Firm value3% | DF2: 3year Firm value3.87% | DG2: 3year Firm value4% | DH2: 3year Firm value5% | DI2: 3year Firm value6% | DJ2: 3year Firm value6.62% | DK2: Average Firm value8% | DL2: 3year Firm value9% | DM2: 3year Average Firm value10% | DN2: 3year Firm value11% | DO2: 3year Average Firm value12% | DP2: 3year Firm value13% | DQ2: 3year Firm value14% | DR2: 3year Average Firm value15% | DS2: Free Cash Flow (3 years Average Based Valuation)1%...15% | DT2: 5 to All Year Average | DU2: Free Cash Flow (5 years Average Based Valuation) 1 % | DV2: Lates Firm value 2% | DW2: Latest Firm value3% | DX2: Firm value3.87% | DY2: Firm value4% | DZ2: Firm value5% | EA2: Firm value6.33% | EB2: Firm value7% | EC2: Firm value8% | ED2: Firm value9% | EE2: Firm value10% | EF2: Firm value11% | EG2: Firm value12% | EH2: Firm value13% | EI2: Firm value14% | EJ2: Firm value15% | EK2: Free Cash Flow (5 years Average Based Valuation)1%...15% | EL2: 10 Years Average | EM2: Free Cash Flow (5 years Average Based Valuation) 1 % | EN2: Lates Firm value 2% | EO2: Latest Firm value3% | EP2: Firm value3.87% | EQ2: Firm value4% | ER2: Firm value5% | ES2: Firm value6% | ET2: Firm value6.62% | EU2: Firm value8% | EV2: Firm value9% | EW2: Firm value10% | EX2: Firm value11% | EY2: Firm value12% | EZ2: Firm value13% | FA2: Firm value14% | FB2: Firm value15% | FC2: Free Cash Flow (10 years Average Based Valuation)1%...15% | FD2: All Year Average | FE2: Free Cash Flow (All years Average Based Valuation) 1 % | FF2: Free Cash Flow (All years Average Based Valuation) 2 % | FG2: Free Cash Flow (All years Average Based Valuation) 3 % | FH2: Free Cash Flow (All years Average Based Valuation) 3.87 % | FI2: Free Cash Flow (All years Average Based Valuation) 4 % | FJ2: Free Cash Flow (All years Average Based Valuation) 5 % | FK2: Free Cash Flow (All years Average Based Valuation) 6 % | FL2: Free Cash Flow (All years Average Based Valuation) 6.62 % | FM2: Free Cash Flow (All years Average Based Valuation) 8 % | FN2: Free Cash Flow (All years Average Based Valuation) 9 % | FO2: Free Cash Flow (All years Average Based Valuation) 10 % | FP2: Free Cash Flow (All years Average Based Valuation) 11 % | FQ2: Free Cash Flow (All years Average Based Valuation) 12 % | FR2: Free Cash Flow (All years Average Based Valuation) 13 % | FS2: Free Cash Flow (All years Average Based Valuation) 14 % | FT2: Free Cash Flow (All years Average Based Valuation) 15 % | FU2: Free Cash Flow (All years Average Based Valuation)1%...15% | FV2: Free Cash Flows to Dereive Market Cap(RHS) | FW2: Free Cash Flow to Dereive Market cap (RHS) 1 % | FX2: Free Cash Flow to Dereive Market cap 2 % | FY2: Free Cash Flow to Dereive Market cap 3 % | FZ2: Free Cash Flow to Dereive Market cap 3.87 % | GA2: Free Cash Flow to Dereive Market cap 4 % | GB2: Free Cash Flow to Dereive Market cap 5 % | GC2: Free Cash Flow to Dereive Market cap 6 % | GD2: Free Cash Flow to Dereive Market cap 6.62 % | GE2: Free Cash Flow to Dereive Market cap 8 % | GF2: Free Cash Flow to Dereive Market cap 9 % | GG2: Free Cash Flow to Dereive Market cap 10 % | GH2: Free Cash Flow to Dereive Market cap ) 11 % | GI2: Free Cash Flow to Dereive Market cap 12 % | GJ2: Free Cash Flow to Dereive Market cap 13 % | GK2: Free Cash Flow to Dereive Market cap 14 % | GL2: Free Cash Flow to Dereive Market cap 15 % | GM2: Free Cash Flow to dereive mcap (1%...15%)
A3: Microsoft | B3: 36707 | C3: 15.426 | D3: 528.60582 | E3: 22.956 | F3: 1334.2 | G3: 6.152 | H3: =(D3/AI3) -> 56.109311 | I3: =(D3/G3) -> 85.924223 | J3: -0.879 | K3: -0.8 | L3: -3.2 | M3: 0 | N3: =(C3+L3+J3+K3+M3) -> 10.547 | P3: 6849000000 | S3: 77.18 | T3: =(S3*P3) -> 5.2860582e+11 | V3: 41.368 | X3: 41.368 | AA3: 0.1 | AB3: 41.368 | AI3: 9.421 | AJ3: 6.152 | AL3: 9.421 | AM3: =D3/AL3 -> 56.109311 | AN3: 6.152 | AO3: =D3/AN3 -> 85.924223 | AQ3: =$D$28/AL3 -> 294.12474 | AR3: =AVERAGE(AQ3:AQ27) -> 175.26694 | AS3: =$D$28/AN3 -> 450.41436 | AT3: =AVERAGE(AS3:AS27) -> 196.80191 | AV3: =(D3/AB3) -> 12.778133 | AW3: =(D3/E3) -> 23.026913 | AX3: 0 | AY3: =(AB3-AX3) -> 41.368 | AZ3: =(D3/AY3) -> 12.778133 | BB3: 10.547 | BC3: 2.05 | BD3: =(BB3/D3)*100 -> 1.9952486 | BE3: =(BC3/D3)*100 -> 0.3878126 | BG3: 77.18 | BH3: 6849000000 | BI3: =(BG3*BH3) -> 5.2860582e+11 | BJ3: 41.368 | BK3: =AY3 -> 41.368 | BL3: 30.308 | BM3: 9.755 | BN3: 1.027 | BO3: =(BL3-BM3-BN3) -> 19.526 | BP3: 23.798 | BQ3: =(BP3-BM3-BN3) -> 13.016 | BS3: =D3 -> 528.60582 | BT3: =E3 -> 22.956 | BU3: =N3 -> 10.547 | BV3: =G3 -> 6.152 | CE3: 36707 | CF3: 528.60582 | CG3: 10.547 | CH3: =(CG3/CF3) -> 0.019952486 | CI3: 0.01 | CJ3: 1 | CK3: =$CG$27/(1+$CI$3)^CJ3 -> 4.890099 | CL3: =$CG$27/(1+$CI$4)^CJ3 -> 4.8421569 | CM3: =$CG$27/(1+$CI$5)^CJ3 -> 4.7951456 | CN3: =$CG$27/(1+$CI$6)^CJ3 -> 4.7549822 | CO3: =$CG$27/(1+$CI$7)^CJ3 -> 4.7490385 | CP3: =$CG$27/(1+$CI$8)^CJ3 -> 4.7038095 | CQ3: =$CG$27/(1+$CI$9)^CJ3 -> 4.659434 | CR3: =$CG$27/(1+$CI$10)^CJ3 -> 4.6323391 | CS3: =$CG$27/(1+$CI$11)^CJ3 -> 4.5731481 | CT3: =$CG$27/(1+$CI$12)^CJ3 -> 4.5311927 | CU3: =$CG$27/(1+$CI$13)^CJ3 -> 4.49 | CV3: =$CG$27/(1+$CI$14)^CJ3 -> 4.4495495 | CW3: =$CG$27/(1+$CI$15)^CJ3 -> 4.4098214 | CX3: =$CG$27/(1+$CI$16)^CJ3 -> 4.3707965 | CY3: =$CG$27/(1+$CI$17)^CJ3 -> 4.3324561 | CZ3: =$CG$27/(1+$CI$18)^CJ3 -> 4.2947826 | DA3: =SUM(CK3:CK52) -> 190.27233 | DB3: =AVERAGE(CG25:CG27) -> 35.285 | DC3: =$DB$3/(1+$CI$3)^CJ3 -> 34.935644 | DD3: =$DB$3/(1+$CI$4)^CJ3 -> 34.593137 | DE3: =$DB$3/(1+$CI$5)^CJ3 -> 34.257282 | DF3: =$DB$3/(1+$CI$6)^CJ3 -> 33.970348 | DG3: =$DB$3/(1+$CI$7)^CJ3 -> 33.927885 | DH3: =$DB$3/(1+$CI$8)^CJ3 -> 33.604762 | DI3: =$DB$3/(1+$CI$9)^CJ3 -> 33.287736 | DJ3: =$DB$3/(1+$CI$10)^CJ3 -> 33.094166 | DK3: =$DB$3/(1+$CI$11)^CJ3 -> 32.671296 | DL3: =$DB$3/(1+$CI$12)^CJ3 -> 32.37156 | DM3: =$DB$3/(1+$CI$13)^CJ3 -> 32.077273 | DN3: =$DB$3/(1+$CI$14)^CJ3 -> 31.788288 | DO3: =$DB$3/(1+$CI$15)^CJ3 -> 31.504464 | DP3: =$DB$3/(1+$CI$16)^CJ3 -> 31.225664 | DQ3: =$DB$3/(1+$CI$17)^CJ3 -> 30.951754 | DR3: =$DB$3/(1+$CI$18)^CJ3 -> 30.682609 | DS3: =SUM(DC3:DC52) -> 1359.3357 | DT3: =AVERAGE(CG23:CG27) -> 39.1554 | DU3: =$DT$3/(1+$CI$3)^CJ3 -> 38.767723 | DV3: =$DT$3/(1+$CI$4)^CJ3 -> 38.387647 | DW3: =$DT$3/(1+$CI$5)^CJ3 -> 38.014951 | DX3: =$DT$3/(1+$CI$6)^CJ3 -> 37.696544 | DY3: =$DT$3/(1+$CI$7)^CJ3 -> 37.649423 | DZ3: =$DT$3/(1+$CI$8)^CJ3 -> 37.290857 | EA3: =$DT$3/(1+$CI$9)^CJ3 -> 36.939057 | EB3: =$DT$3/(1+$CI$10)^CJ3 -> 36.724254 | EC3: =$DT$3/(1+$CI$11)^CJ3 -> 36.255 | ED3: =$DT$3/(1+$CI$12)^CJ3 -> 35.922385 | EE3: =$DT$3/(1+$CI$13)^CJ3 -> 35.595818 | EF3: =$DT$3/(1+$CI$14)^CJ3 -> 35.275135 | EG3: =$DT$3/(1+$CI$15)^CJ3 -> 34.960179 | EH3: =$DT$3/(1+$CI$16)^CJ3 -> 34.650796 | EI3: =$DT$3/(1+$CI$17)^CJ3 -> 34.346842 | EJ3: =$DT$3/(1+$CI$18)^CJ3 -> 34.048174 | EK3: =SUM(DU3:DU52) -> 1508.4408 | EL3: =AVERAGE(CG18:CG27) -> 31.2037 | EM3: =$EL$3/(1+$CI$3)^CJ3 -> 30.894752 | EN3: =$EL$3/(1+$CI$4)^CJ3 -> 30.591863 | EO3: =$EL$3/(1+$CI$5)^CJ3 -> 30.294854 | EP3: =$EL$3/(1+$CI$6)^CJ3 -> 30.041109 | EQ3: =$EL$3/(1+$CI$7)^CJ3 -> 30.003558 | ER3: =$EL$3/(1+$CI$8)^CJ3 -> 29.71781 | ES3: =$EL$3/(1+$CI$9)^CJ3 -> 29.437453 | ET3: =$EL$3/(1+$CI$10)^CJ3 -> 29.266273 | EU3: =$EL$3/(1+$CI$11)^CJ3 -> 28.892315 | EV3: =$EL$3/(1+$CI$12)^CJ3 -> 28.627248 | EW3: =$EL$3/(1+$CI$13)^CJ3 -> 28.367 | EX3: =$EL$3/(1+$CI$14)^CJ3 -> 28.111441 | EY3: =$EL$3/(1+$CI$15)^CJ3 -> 27.860446 | EZ3: =$EL$3/(1+$CI$16)^CJ3 -> 27.613894 | FA3: =$EL$3/(1+$CI$17)^CJ3 -> 27.371667 | FB3: =$EL$3/(1+$CI$18)^CJ3 -> 27.133652 | FC3: =SUM(EM3:EM52) -> 1202.1058 | FD3: =AVERAGE(CG3:CG27) -> 22.11996 | FE3: =$FD$3/(1+$CI$3)^CJ3 -> 21.90095 | FF3: =$FD$3/(1+$CI$4)^CJ3 -> 21.686235 | FG3: =$FD$3/(1+$CI$5)^CJ3 -> 21.475689 | FH3: =$FD$3/(1+$CI$6)^CJ3 -> 21.295812 | FI3: =$FD$3/(1+$CI$7)^CJ3 -> 21.269192 | FJ3: =$FD$3/(1+$CI$8)^CJ3 -> 21.066629 | FK3: =$FD$3/(1+$CI$9)^CJ3 -> 20.867887 | FL3: =$FD$3/(1+$CI$10)^CJ3 -> 20.746539 | FM3: =$FD$3/(1+$CI$11)^CJ3 -> 20.481444 | FN3: =$FD$3/(1+$CI$12)^CJ3 -> 20.293541 | FO3: =$FD$3/(1+$CI$13)^CJ3 -> 20.109055 | FP3: =$FD$3/(1+$CI$14)^CJ3 -> 19.927892 | FQ3: =$FD$3/(1+$CI$15)^CJ3 -> 19.749964 | FR3: =$FD$3/(1+$CI$16)^CJ3 -> 19.575186 | FS3: =$FD$3/(1+$CI$17)^CJ3 -> 19.403474 | FT3: =$FD$3/(1+$CI$18)^CJ3 -> 19.234748 | FU3: =SUM(FE3:FE52) -> 852.15961 | FV3: =AVERAGE(CH3:CH27) -> 0.040692862 | FW3: =$FV$3/(1+$CI$3)^CJ3 -> 0.040289963 | FX3: =$FV$3/(1+$CI$4)^CJ3 -> 0.039894963 | FY3: =$FV$3/(1+$CI$5)^CJ3 -> 0.039507633 | FZ3: =$FV$3/(1+$CI$6)^CJ3 -> 0.039176723 | GA3: =$FV$3/(1+$CI$7)^CJ3 -> 0.039127752 | GB3: =$FV$3/(1+$CI$8)^CJ3 -> 0.038755107 | GC3: =$FV$3/(1+$CI$9)^CJ3 -> 0.038389493 | GD3: =$FV$3/(1+$CI$10)^CJ3 -> 0.038166256 | GE3: =$FV$3/(1+$CI$11)^CJ3 -> 0.037678576 | GF3: =$FV$3/(1+$CI$12)^CJ3 -> 0.037332901 | GG3: =$FV$3/(1+$CI$13)^CJ3 -> 0.036993511 | GH3: =$FV$3/(1+$CI$14)^CJ3 -> 0.036660236 | GI3: =$FV$3/(1+$CI$15)^CJ3 -> 0.036332913 | GJ3: =$FV$3/(1+$CI$16)^CJ3 -> 0.036011383 | GK3: =$FV$3/(1+$CI$17)^CJ3 -> 0.035695493 | GL3: =$FV$3/(1+$CI$18)^CJ3 -> 0.035385098 | GM3: =SUM(FW3:FW52) -> 1.5676707
A4: Microsoft | B4: 37072 | C4: 15.025 | D4: 560.142 | E4: 25.296 | F4: 1158.3 | G4: 7.916 | H4: =(D4/AI4) -> 76.251293 | I4: =(D4/G4) -> 70.760738 | J4: -1.103 | K4: -1.3 | L4: -0.303 | M4: 0 | N4: =(C4+L4+J4+K4+M4) -> 12.319 | P4: 6831000000 | Q4: =(P4-P3)/P3*100 -> -0.26281209 | S4: 82 | T4: =(S4*P4) -> 560142000000 | U4: =(D4-D3)/D3*100 -> 5.9659162 | V4: 47.289 | W4: =(V4-V3)/V3*100 -> 14.312996 | X4: 45.377 | Y4: =(X4-X3)/X3*100 -> 9.6910656 | AA4: 0.1 | AB4: 47.289 | AC4: 41.368 | AD4: =(G3/AA3) -> 61.52 | AE4: =(D4-AC4-AD4) -> 457.254 | AF4: =((((D4-AD4)/(G4)*AA4)-1)/(1+(D4-AD4)/(G4))) -> 0.082809582 | AG4: =(1+AF4)/(1+AA4) -> 0.98437235 | AI4: 7.346 | AJ4: 7.916 | AL4: 7.346 | AM4: =D4/AL4 -> 76.251293 | AN4: 7.916 | AO4: =D4/AN4 -> 70.760738 | AQ4: =$D$28/AL4 -> 377.20517 | AS4: =$D$28/AN4 -> 350.04411 | AV4: =(D4/AB4) -> 11.84508 | AW4: =(D4/E4) -> 22.143501 | AX4: 1.912 | AY4: =(AB4-AX4) -> 45.377 | AZ4: =(D4/AY4) -> 12.344183 | BB4: 12.319 | BC4: 4.662 | BD4: =(BB4/D4)*100 -> 2.1992638 | BE4: =(BC4/D4)*100 -> 0.83228896 | BG4: 82 | BH4: 6831000000 | BI4: =(BG4*BH4) -> 560142000000 | BJ4: 47.289 | BK4: =AY4 -> 45.377 | BL4: 39.21 | BM4: 9.254 | BN4: 2.287 | BO4: =(BL4-BM4-BN4) -> 27.669 | BP4: 31.6 | BQ4: =(BP4-BM4-BN4) -> 20.059 | BS4: =D4 -> 560.142 | BT4: =E4 -> 25.296 | BU4: =N4 -> 12.319 | BV4: =G4 -> 7.916 | CE4: 37072 | CF4: 560.142 | CG4: 12.319 | CH4: =(CG4/CF4) -> 0.021992638 | CI4: 0.02 | CJ4: 2 | CK4: =$CG$27/(1+$CI$3)^CJ4 -> 4.8416822 | CL4: =$CG$27/(1+$CI$4)^CJ4 -> 4.7472126 | CM4: =$CG$27/(1+$CI$5)^CJ4 -> 4.6554812 | CN4: =$CG$27/(1+$CI$6)^CJ4 -> 4.5778205 | CO4: =$CG$27/(1+$CI$7)^CJ4 -> 4.5663831 | CP4: =$CG$27/(1+$CI$8)^CJ4 -> 4.4798186 | CQ4: =$CG$27/(1+$CI$9)^CJ4 -> 4.3956924 | CR4: =$CG$27/(1+$CI$10)^CJ4 -> 4.3447188 | CS4: =$CG$27/(1+$CI$11)^CJ4 -> 4.2343964 | CT4: =$CG$27/(1+$CI$12)^CJ4 -> 4.1570575 | CU4: =$CG$27/(1+$CI$13)^CJ4 -> 4.0818182 | CV4: =$CG$27/(1+$CI$14)^CJ4 -> 4.0086032 | CW4: =$CG$27/(1+$CI$15)^CJ4 -> 3.9373406 | CX4: =$CG$27/(1+$CI$16)^CJ4 -> 3.8679615 | CY4: =$CG$27/(1+$CI$17)^CJ4 -> 3.8004001 | CZ4: =$CG$27/(1+$CI$18)^CJ4 -> 3.7345936 | DA4: =SUM(CL3:CL52) -> 152.96436 | DB4: =AVERAGE(CG23:CG27) -> 39.1554 | DC4: =$DB$3/(1+$CI$3)^CJ4 -> 34.589746 | DD4: =$DB$3/(1+$CI$4)^CJ4 -> 33.91484 | DE4: =$DB$3/(1+$CI$5)^CJ4 -> 33.259497 | DF4: =$DB$3/(1+$CI$6)^CJ4 -> 32.704677 | DG4: =$DB$3/(1+$CI$7)^CJ4 -> 32.622966 | DH4: =$DB$3/(1+$CI$8)^CJ4 -> 32.004535 | DI4: =$DB$3/(1+$CI$9)^CJ4 -> 31.403524 | DJ4: =$DB$3/(1+$CI$10)^CJ4 -> 31.039361 | DK4: =$DB$3/(1+$CI$11)^CJ4 -> 30.2512 | DL4: =$DB$3/(1+$CI$12)^CJ4 -> 29.698679 | DM4: =$DB$3/(1+$CI$13)^CJ4 -> 29.161157 | DN4: =$DB$3/(1+$CI$14)^CJ4 -> 28.638098 | DO4: =$DB$3/(1+$CI$15)^CJ4 -> 28.128986 | DP4: =$DB$3/(1+$CI$16)^CJ4 -> 27.633331 | DQ4: =$DB$3/(1+$CI$17)^CJ4 -> 27.150662 | DR4: =$DB$3/(1+$CI$18)^CJ4 -> 26.680529 | DS4: =SUM(DD3:DD52) -> 1092.8017 | DT4: =AVERAGE(CG18:CG27) -> 31.2037 | DU4: =$DT$3/(1+$CI$3)^CJ4 -> 38.383884 | DV4: =$DT$3/(1+$CI$4)^CJ4 -> 37.634948 | DW4: =$DT$3/(1+$CI$5)^CJ4 -> 36.90772 | DX4: =$DT$3/(1+$CI$6)^CJ4 -> 36.292042 | DY4: =$DT$3/(1+$CI$7)^CJ4 -> 36.201368 | DZ4: =$DT$3/(1+$CI$8)^CJ4 -> 35.515102 | EA4: =$DT$3/(1+$CI$9)^CJ4 -> 34.848167 | EB4: =$DT$3/(1+$CI$10)^CJ4 -> 34.444058 | EC4: =$DT$3/(1+$CI$11)^CJ4 -> 33.569444 | ED4: =$DT$3/(1+$CI$12)^CJ4 -> 32.956317 | EE4: =$DT$3/(1+$CI$13)^CJ4 -> 32.359835 | EF4: =$DT$3/(1+$CI$14)^CJ4 -> 31.779401 | EG4: =$DT$3/(1+$CI$15)^CJ4 -> 31.214445 | EH4: =$DT$3/(1+$CI$16)^CJ4 -> 30.664422 | EI4: =$DT$3/(1+$CI$17)^CJ4 -> 30.128809 | EJ4: =$DT$3/(1+$CI$18)^CJ4 -> 29.607108 | EK4: =SUM(DV3:DV52) -> 1212.6708 | EL4: =AVERAGE(CG3:CG27) -> 22.11996 | EM4: =$EL$3/(1+$CI$3)^CJ4 -> 30.588864 | EN4: =$EL$3/(1+$CI$4)^CJ4 -> 29.992022 | EO4: =$EL$3/(1+$CI$5)^CJ4 -> 29.41248 | EP4: =$EL$3/(1+$CI$6)^CJ4 -> 28.921834 | EQ4: =$EL$3/(1+$CI$7)^CJ4 -> 28.849575 | ER4: =$EL$3/(1+$CI$8)^CJ4 -> 28.302676 | ES4: =$EL$3/(1+$CI$9)^CJ4 -> 27.771182 | ET4: =$EL$3/(1+$CI$10)^CJ4 -> 27.44914 | EU4: =$EL$3/(1+$CI$11)^CJ4 -> 26.752143 | EV4: =$EL$3/(1+$CI$12)^CJ4 -> 26.26353 | EW4: =$EL$3/(1+$CI$13)^CJ4 -> 25.788182 | EX4: =$EL$3/(1+$CI$14)^CJ4 -> 25.325623 | EY4: =$EL$3/(1+$CI$15)^CJ4 -> 24.875399 | EZ4: =$EL$3/(1+$CI$16)^CJ4 -> 24.437074 | FA4: =$EL$3/(1+$CI$17)^CJ4 -> 24.010234 | FB4: =$EL$3/(1+$CI$18)^CJ4 -> 23.59448 | FC4: =SUM(EN3:EN52) -> 966.40091 | FE4: =$FD$3/(1+$CI$3)^CJ4 -> 21.684109 | FF4: =$FD$3/(1+$CI$4)^CJ4 -> 21.261015 | FG4: =$FD$3/(1+$CI$5)^CJ4 -> 20.850184 | FH4: =$FD$3/(1+$CI$6)^CJ4 -> 20.50237 | FI4: =$FD$3/(1+$CI$7)^CJ4 -> 20.451146 | FJ4: =$FD$3/(1+$CI$8)^CJ4 -> 20.063456 | FK4: =$FD$3/(1+$CI$9)^CJ4 -> 19.686686 | FL4: =$FD$3/(1+$CI$10)^CJ4 -> 19.458393 | FM4: =$FD$3/(1+$CI$11)^CJ4 -> 18.9643 | FN4: =$FD$3/(1+$CI$12)^CJ4 -> 18.617928 | FO4: =$FD$3/(1+$CI$13)^CJ4 -> 18.280959 | FP4: =$FD$3/(1+$CI$14)^CJ4 -> 17.953056 | FQ4: =$FD$3/(1+$CI$15)^CJ4 -> 17.633897 | FR4: =$FD$3/(1+$CI$16)^CJ4 -> 17.323173 | FS4: =$FD$3/(1+$CI$17)^CJ4 -> 17.020591 | FT4: =$FD$3/(1+$CI$18)^CJ4 -> 16.725868 | FU4: =SUM(FF3:FF52) -> 685.07099 | FW4: =$FV$3/(1+$CI$3)^CJ4 -> 0.039891052 | FX4: =$FV$3/(1+$CI$4)^CJ4 -> 0.039112709 | FY4: =$FV$3/(1+$CI$5)^CJ4 -> 0.038356926 | FZ4: =$FV$3/(1+$CI$6)^CJ4 -> 0.037717072 | GA4: =$FV$3/(1+$CI$7)^CJ4 -> 0.037622839 | GB4: =$FV$3/(1+$CI$8)^CJ4 -> 0.036909626 | GC4: =$FV$3/(1+$CI$9)^CJ4 -> 0.036216503 | GD4: =$FV$3/(1+$CI$10)^CJ4 -> 0.035796526 | GE4: =$FV$3/(1+$CI$11)^CJ4 -> 0.034887571 | GF4: =$FV$3/(1+$CI$12)^CJ4 -> 0.034250368 | GG4: =$FV$3/(1+$CI$13)^CJ4 -> 0.033630465 | GH4: =$FV$3/(1+$CI$14)^CJ4 -> 0.03302724 | GI4: =$FV$3/(1+$CI$15)^CJ4 -> 0.032440101 | GJ4: =$FV$3/(1+$CI$16)^CJ4 -> 0.03186848 | GK4: =$FV$3/(1+$CI$17)^CJ4 -> 0.031311836 | GL4: =$FV$3/(1+$CI$18)^CJ4 -> 0.03076965 | GM4: =SUM(FX3:FX52) -> 1.2602871
A5: Microsoft | B5: 37437 | C5: 16.64 | D5: 486.50928 | E5: 28.365 | F5: 879.4 | G5: 8.226 | H5: =(D5/AI5) -> 62.141944 | I5: =(D5/G5) -> 59.142874 | J5: -0.77 | K5: -1.9 | L5: -0.231 | M5: 0 | N5: =(C5+L5+J5+K5+M5) -> 13.739 | P5: 6704000000 | Q5: =(P5-P4)/P4*100 -> -1.8591714 | S5: 72.57 | T5: =(S5*P5) -> 4.8650928e+11 | U5: =(D5-D4)/D4*100 -> -13.145367 | V5: 54.842 | W5: =(V5-V4)/V4*100 -> 15.972002 | X5: 53.173 | Y5: =(X5-X4)/X4*100 -> 17.18051 | AA5: 0.1 | AB5: 54.842 | AC5: 47.289 | AD5: =(G4/AA5) -> 79.16 | AE5: =(D5-AC5-AD5) -> 360.06028 | AF5: =((((D5-AD5)/(G5)*AA5)-1)/(1+(D5-AD5)/(G5))) -> 0.078226328 | AG5: =(1+AF5)/(1+AA5) -> 0.98020575 | AI5: 7.829 | AJ5: 8.226 | AL5: 7.829 | AM5: =D5/AL5 -> 62.141944 | AN5: 8.226 | AO5: =D5/AN5 -> 59.142874 | AQ5: =$D$28/AL5 -> 353.93398 | AS5: =$D$28/AN5 -> 336.85256 | AV5: =(D5/AB5) -> 8.8711075 | AW5: =(D5/E5) -> 17.151746 | AX5: 1.669 | AY5: =(AB5-AX5) -> 53.173 | AZ5: =(D5/AY5) -> 9.1495548 | BB5: 13.739 | BC5: 3.666 | BD5: =(BB5/D5)*100 -> 2.8239955 | BE5: =(BC5/D5)*100 -> 0.75353136 | BG5: 72.57 | BH5: 6704000000 | BI5: =(BG5*BH5) -> 4.8650928e+11 | BJ5: 54.842 | BK5: =AY5 -> 53.173 | BL5: 48.576 | BM5: 12.744 | BN5: 0.06 | BO5: =(BL5-BM5-BN5) -> 35.772 | BP5: 38.652 | BQ5: =(BP5-BM5-BN5) -> 25.848 | BS5: =D5 -> 486.50928 | BT5: =E5 -> 28.365 | BU5: =N5 -> 13.739 | BV5: =G5 -> 8.226 | CE5: 37437 | CF5: 486.50928 | CG5: 13.739 | CH5: =(CG5/CF5) -> 0.028239955 | CI5: 0.03 | CJ5: 3 | CK5: =$CG$27/(1+$CI$3)^CJ5 -> 4.7937447 | CL5: =$CG$27/(1+$CI$4)^CJ5 -> 4.65413 | CM5: =$CG$27/(1+$CI$5)^CJ5 -> 4.5198847 | CN5: =$CG$27/(1+$CI$6)^CJ5 -> 4.4072596 | CO5: =$CG$27/(1+$CI$7)^CJ5 -> 4.390753 | CP5: =$CG$27/(1+$CI$8)^CJ5 -> 4.2664939 | CQ5: =$CG$27/(1+$CI$9)^CJ5 -> 4.1468796 | CR5: =$CG$27/(1+$CI$10)^CJ5 -> 4.0749566 | CS5: =$CG$27/(1+$CI$11)^CJ5 -> 3.9207374 | CT5: =$CG$27/(1+$CI$12)^CJ5 -> 3.8138142 | CU5: =$CG$27/(1+$CI$13)^CJ5 -> 3.7107438 | CV5: =$CG$27/(1+$CI$14)^CJ5 -> 3.6113542 | CW5: =$CG$27/(1+$CI$15)^CJ5 -> 3.5154826 | CX5: =$CG$27/(1+$CI$16)^CJ5 -> 3.4229748 | CY5: =$CG$27/(1+$CI$17)^CJ5 -> 3.3336843 | CZ5: =$CG$27/(1+$CI$18)^CJ5 -> 3.2474727 | DA5: =SUM(CM3:CM52) -> 125.56522 | DB5: =AVERAGE(CG18:CG27) -> 31.2037 | DC5: =$DB$3/(1+$CI$3)^CJ5 -> 34.247273 | DD5: =$DB$3/(1+$CI$4)^CJ5 -> 33.249844 | DE5: =$DB$3/(1+$CI$5)^CJ5 -> 32.290773 | DF5: =$DB$3/(1+$CI$6)^CJ5 -> 31.486162 | DG5: =$DB$3/(1+$CI$7)^CJ5 -> 31.368237 | DH5: =$DB$3/(1+$CI$8)^CJ5 -> 30.48051 | DI5: =$DB$3/(1+$CI$9)^CJ5 -> 29.625966 | DJ5: =$DB$3/(1+$CI$10)^CJ5 -> 29.112137 | DK5: =$DB$3/(1+$CI$11)^CJ5 -> 28.010371 | DL5: =$DB$3/(1+$CI$12)^CJ5 -> 27.246494 | DM5: =$DB$3/(1+$CI$13)^CJ5 -> 26.510143 | DN5: =$DB$3/(1+$CI$14)^CJ5 -> 25.800088 | DO5: =$DB$3/(1+$CI$15)^CJ5 -> 25.115166 | DP5: =$DB$3/(1+$CI$16)^CJ5 -> 24.454275 | DQ5: =$DB$3/(1+$CI$17)^CJ5 -> 23.81637 | DR5: =$DB$3/(1+$CI$18)^CJ5 -> 23.20046 | DS5: =SUM(DE3:DE52) -> 897.05786 | DT5: =AVERAGE(CG3:CG27) -> 22.11996 | DU5: =$DT$3/(1+$CI$3)^CJ5 -> 38.003845 | DV5: =$DT$3/(1+$CI$4)^CJ5 -> 36.897008 | DW5: =$DT$3/(1+$CI$5)^CJ5 -> 35.832738 | DX5: =$DT$3/(1+$CI$6)^CJ5 -> 34.939869 | DY5: =$DT$3/(1+$CI$7)^CJ5 -> 34.809008 | DZ5: =$DT$3/(1+$CI$8)^CJ5 -> 33.823907 | EA5: =$DT$3/(1+$CI$9)^CJ5 -> 32.875629 | EB5: =$DT$3/(1+$CI$10)^CJ5 -> 32.305438 | EC5: =$DT$3/(1+$CI$11)^CJ5 -> 31.082819 | ED5: =$DT$3/(1+$CI$12)^CJ5 -> 30.235153 | EE5: =$DT$3/(1+$CI$13)^CJ5 -> 29.418032 | EF5: =$DT$3/(1+$CI$14)^CJ5 -> 28.630091 | EG5: =$DT$3/(1+$CI$15)^CJ5 -> 27.87004 | EH5: =$DT$3/(1+$CI$16)^CJ5 -> 27.136656 | EI5: =$DT$3/(1+$CI$17)^CJ5 -> 26.42878 | EJ5: =$DT$3/(1+$CI$18)^CJ5 -> 25.745311 | EK5: =SUM(DW3:DW52) -> 995.45585 | EM5: =$EL$3/(1+$CI$3)^CJ5 -> 30.286004 | EN5: =$EL$3/(1+$CI$4)^CJ5 -> 29.403943 | EO5: =$EL$3/(1+$CI$5)^CJ5 -> 28.555806 | EP5: =$EL$3/(1+$CI$6)^CJ5 -> 27.844261 | EQ5: =$EL$3/(1+$CI$7)^CJ5 -> 27.739976 | ER5: =$EL$3/(1+$CI$8)^CJ5 -> 26.954929 | ES5: =$EL$3/(1+$CI$9)^CJ5 -> 26.199228 | ET5: =$EL$3/(1+$CI$10)^CJ5 -> 25.744832 | EU5: =$EL$3/(1+$CI$11)^CJ5 -> 24.770503 | EV5: =$EL$3/(1+$CI$12)^CJ5 -> 24.094982 | EW5: =$EL$3/(1+$CI$13)^CJ5 -> 23.443802 | EX5: =$EL$3/(1+$CI$14)^CJ5 -> 22.815877 | EY5: =$EL$3/(1+$CI$15)^CJ5 -> 22.210177 | EZ5: =$EL$3/(1+$CI$16)^CJ5 -> 21.625729 | FA5: =$EL$3/(1+$CI$17)^CJ5 -> 21.061609 | FB5: =$EL$3/(1+$CI$18)^CJ5 -> 20.516939 | FC5: =SUM(EO3:EO52) -> 793.29813 | FE5: =$FD$3/(1+$CI$3)^CJ5 -> 21.469415 | FF5: =$FD$3/(1+$CI$4)^CJ5 -> 20.844132 | FG5: =$FD$3/(1+$CI$5)^CJ5 -> 20.242897 | FH5: =$FD$3/(1+$CI$6)^CJ5 -> 19.738491 | FI5: =$FD$3/(1+$CI$7)^CJ5 -> 19.664564 | FJ5: =$FD$3/(1+$CI$8)^CJ5 -> 19.108053 | FK5: =$FD$3/(1+$CI$9)^CJ5 -> 18.572345 | FL5: =$FD$3/(1+$CI$10)^CJ5 -> 18.250228 | FM5: =$FD$3/(1+$CI$11)^CJ5 -> 17.559537 | FN5: =$FD$3/(1+$CI$12)^CJ5 -> 17.080668 | FO5: =$FD$3/(1+$CI$13)^CJ5 -> 16.619053 | FP5: =$FD$3/(1+$CI$14)^CJ5 -> 16.173924 | FQ5: =$FD$3/(1+$CI$15)^CJ5 -> 15.744551 | FR5: =$FD$3/(1+$CI$16)^CJ5 -> 15.330242 | FS5: =$FD$3/(1+$CI$17)^CJ5 -> 14.930343 | FT5: =$FD$3/(1+$CI$18)^CJ5 -> 14.544233 | FU5: =SUM(FG3:FG52) -> 562.36033 | FW5: =$FV$3/(1+$CI$3)^CJ5 -> 0.039496091 | FX5: =$FV$3/(1+$CI$4)^CJ5 -> 0.038345793 | FY5: =$FV$3/(1+$CI$5)^CJ5 -> 0.037239734 | FZ5: =$FV$3/(1+$CI$6)^CJ5 -> 0.036311806 | GA5: =$FV$3/(1+$CI$7)^CJ5 -> 0.036175806 | GB5: =$FV$3/(1+$CI$8)^CJ5 -> 0.035152025 | GC5: =$FV$3/(1+$CI$9)^CJ5 -> 0.034166512 | GD5: =$FV$3/(1+$CI$10)^CJ5 -> 0.033573932 | GE5: =$FV$3/(1+$CI$11)^CJ5 -> 0.032303306 | GF5: =$FV$3/(1+$CI$12)^CJ5 -> 0.031422356 | GG5: =$FV$3/(1+$CI$13)^CJ5 -> 0.03057315 | GH5: =$FV$3/(1+$CI$14)^CJ5 -> 0.02975427 | GI5: =$FV$3/(1+$CI$15)^CJ5 -> 0.028964376 | GJ5: =$FV$3/(1+$CI$16)^CJ5 -> 0.028202195 | GK5: =$FV$3/(1+$CI$17)^CJ5 -> 0.027466523 | GL5: =$FV$3/(1+$CI$18)^CJ5 -> 0.026756218 | GM5: =SUM(FY3:FY52) -> 1.0345431
